<?xml version="1.0"?>
<robot name="water_maxi">
  <link name="base_link">
    <visual name="Base">
      <geometry>
        <mesh filename="package://water_maxi_description/models/Base_Link.stl" scale="0.01 0.01 0.01"/>
      </geometry>
      <material>
        <color rgba="0 0.8 0 1"/>
      </material>
    </visual>
  </link>

  <link name="arm_link1">
    <visual name="schwenkarm">
      <geometry>
        <mesh filename="package://water_maxi_description/models/SchwenkArm_Link.stl" scale="0.01 0.01 0.01"/>        
      </geometry>
      
    </visual>
  </link>

  <joint name="base_to_arm" type="continuous">
    <parent link="base_link"/>
    <child link="arm_link1"/>    
    <origin xyz="-0.55 0 2" rpy="0.0 1.57 -1.57"/>
    
  </joint>

</robot>