<?xml version="1.0"?>
<robot name="water_maxi">

  <link name="world"/>

  <link name="base_link">
    <visual name="base">
      <geometry>
        <mesh filename="package://water_maxi_description/models/Base_Link.stl" scale="0.01 0.01 0.01"/>
      </geometry>
      <material name="green">
        <color rgba="0 0.8 0 1"/>
      </material>
    </visual>
  </link>

  <joint name="world_to_Base" type="fixed">
    <parent link="world"/>
    <child link="base_link"/>
    <origin xyz="0 0 0" rpy="0 0 0"/>
    <axis xyz="0 0 0"/>
  </joint>

  <link name="arm_link1">
    <visual>
      <geometry>
        <mesh filename="package://water_maxi_description/models/SchwenkArm_Link.stl" scale="0.01 0.01 0.01"/>        
      </geometry>   
      <material name="grey">
        <color rgba="0.8 0.8 0.8 1"/>
      </material>   
    </visual>
  </link>

  <joint name="base_to_schwenkarm" type="continuous">
    <parent link="base_link"/>
    <child link="arm_link1"/>    
    <origin xyz="-0.55 0 2" rpy="0.0 1.57 -1.57"/>  
    <axis xyz="0.0 1.0 0.0"/>
      
  </joint>

</robot>